Workbook

Sheet 케이스 결과
A1: 범주 | B1: 물음(입력) | C1: 뽑은 경유지 | D1: 도착 마감 | E1: 이동수단 | F1: 순서 | G1: 거절 | H1: 되묻기 | I1: 판정 | J1: 실패 사유 | K1: 메모
A2: basic | B2: 출근길에 올리브영 들르고 빵도 사가고 싶어 | C2: 올리브영, 파리바게뜨, 베이커리 | F2: auto | I2: 통과
A3: basic | B3: 9시까지 회사 가야 하는데 커피 사고 은행도 들러야 해 | C3: 스타벅스, 카페, 은행 | D3: 09:00 | F3: auto | I3: 통과
A4: basic | B4: 택배 부치고 약국 갔다가 회사 | C4: 우체국, 편의점, 약국 | F4: auto | I4: 통과
A5: basic | B5: 강남역 스타벅스 들렀다 가자 | C5: 스타벅스 | F5: auto | I5: 통과
A6: basic | B6: 지하철로 갈래 | E6: transit | F6: auto | I6: 통과
A7: basic | B7: 문 연 약국만 | C7: 약국 | F7: auto | I7: 통과
A8: basic | B8: 은행 먼저 갔다가 우체국 | C8: 은행 | F8: locked | I8: 통과
A9: basic | B9: 올리브영 3개 들러서 비교해볼래 | C9: 올리브영 | F9: auto | I9: 통과
A10: typo | B10: 올리브용 들르고 싶어 | F10: auto | H10: 어디를 들르실지 다시 말씀해 주세요. | I10: 실패 | J10: qhas 올리브영 | K10: 오타 교정 — Codex 통과, 목 실패
A11: typo | B11: 스타벅쓰 들렀다 가자 | F11: auto | H11: 어디를 들르실지 다시 말씀해 주세요. | I11: 실패 | J11: qhas 스타벅스 | K11: 오타 교정
A12: typo | B12: 파리바게트 들러줘 | F12: auto | H12: 어디를 들르실지 다시 말씀해 주세요. | I12: 실패 | J12: qhas 파리바게뜨 | K12: 표기 오류 교정
A13: typo | B13: 편의젬 들러야해 | F13: auto | H13: 어디를 들르실지 다시 말씀해 주세요. | I13: 실패 | J13: qhas 편의점,CU,GS25 | K13: 오타 교정
A14: typo | B14: 9시 까 지 도착 | F14: auto | I14: 실패 | J14: at=null≠540 | K14: 띄어쓰기 파괴
A15: abbrev | B15: 올영 들러야 해 | F15: auto | H15: 어디를 들르실지 다시 말씀해 주세요. | I15: 실패 | J15: qhas 올리브영 | K15: 줄임말
A16: abbrev | B16: 스벅에서 커피 | C16: 스타벅스, 카페 | F16: auto | I16: 통과 | K16: 스벅은 못 잡아도 커피로 잡힘
A17: abbrev | B17: 파바 들르자 | F17: auto | H17: 어디를 들르실지 다시 말씀해 주세요. | I17: 실패 | J17: qhas 파리바게뜨 | K17: 줄임말
A18: abbrev | B18: 다이소 들를래 | F18: auto | H18: 어디를 들르실지 다시 말씀해 주세요. | I18: 통과 | K18: 사전 밖 브랜드 — 되묻는다
A19: abbrev | B19: 메가커피 갈래 | C19: 스타벅스, 카페 | F19: auto | I19: 통과 | K19: 커피로 잡힘
A20: spacing | B20: 올리브영들르고빵도사고싶어 | C20: 올리브영, 파리바게뜨, 베이커리 | F20: auto | I20: 통과 | K20: 띄어쓰기 없음
A21: spacing | B21: 9시까지회사 | D21: 09:00 | F21: auto | I21: 통과
A22: spacing | B22: 약국이랑은행 | C22: 약국, 은행 | F22: auto | I22: 통과
A23: spacing | B23: 커피사고은행들러야해 | C23: 스타벅스, 카페, 은행 | F23: auto | I23: 통과
A24: english | B24: olive young 들러줘 | F24: auto | H24: 어디를 들르실지 다시 말씀해 주세요. | I24: 실패 | J24: qhas 올리브영 | K24: 영문 브랜드
A25: english | B25: starbucks 들렀다 가자 | F25: auto | H25: 어디를 들르실지 다시 말씀해 주세요. | I25: 실패 | J25: qhas 스타벅스 | K25: 영문 브랜드
A26: english | B26: CU 들러서 담배 | C26: CU | F26: auto | I26: 통과 | K26: 영문이 정식 표기
A27: english | B27: GS25 잠깐 | C27: GS25 | F27: auto | I27: 통과
A28: english | B28: pharmacy 들러야 해 | F28: auto | H28: 어디를 들르실지 다시 말씀해 주세요. | I28: 실패 | J28: qhas 약국 | K28: 영어 카테고리
A29: numtrap | B29: 2호선 타고 갈래 | F29: auto | H29: 어디를 들르실지 다시 말씀해 주세요. | I29: 실패 | J29: m=null≠transit | K29: 2를 개수로 읽으면 안 된다
A30: numtrap | B30: 3번 출구에서 만나기로 했어 | F30: auto | I30: 통과 | K30: 3은 출구 번호
A31: numtrap | B31: 올리브영 1층에 있어 | C31: 올리브영 | F31: auto | I31: 통과 | K31: 1은 층수
A32: numtrap | B32: 24시간 편의점 들러줘 | C32: CU, GS25, 편의점 | F32: auto | I32: 통과 | K32: 24는 개수가 아니다
A33: numtrap | B33: CU 여의도2호점 | C33: CU | F33: auto | I33: 통과 | K33: 2호점은 개수가 아니다
A34: numtrap | B34: 샌드위치 2개 사기 | F34: auto | I34: 통과 | K34: 물건 개수
A35: numtrap | B35: 아메리카노 두 잔 사고 | C35: 스타벅스, 카페 | F35: auto | I35: 통과 | K35: 잔은 장소 단위가 아니다
A36: numtrap | B36: 5천원짜리 빵 | C36: 파리바게뜨, 베이커리 | F36: auto | I36: 통과 | K36: 금액
A37: timetrap | B37: 3시간 걸려도 괜찮아 | F37: auto | I37: 통과 | K37: 길찾기 맥락 — 거절하면 안 된다
A38: timetrap | B38: 5분 거리에 있는 편의점 | C38: CU, GS25, 편의점 | F38: auto | I38: 통과
A39: timetrap | B39: 1시간 뒤에 출발할 거야 | F39: auto | I39: 통과 | K39: 길찾기 맥락 — 거절하면 안 된다
A40: timetrap | B40: 10분만 들렀다 갈게 | F40: auto | H40: 어디를 들르실지 다시 말씀해 주세요. | I40: 통과 | K40: 체류시간
...

Sheet 요약
A1: 지표 | B1: 값
A2: 전체 | B2: =COUNTA('케이스 결과'!B2:B148)
A3: 통과 | B3: =COUNTIF('케이스 결과'!I2:I148,"통과")
A4: 실패 | B4: =COUNTIF('케이스 결과'!I2:I148,"실패")
A5: 미검증 | B5: =COUNTIF('케이스 결과'!I2:I148,"미검증")
A6: 검증 통과율 | B6: =IFERROR(B3/(B3+B4),"")
A8: 범주 | B8: 전체 | C8: 실패
A9: abbrev | B9: =COUNTIF('케이스 결과'!A2:A148,A9) | C9: =COUNTIFS('케이스 결과'!A2:A148,A9,'케이스 결과'!I2:I148,"실패")
A10: abuse | B10: =COUNTIF('케이스 결과'!A2:A148,A10) | C10: =COUNTIFS('케이스 결과'!A2:A148,A10,'케이스 결과'!I2:I148,"실패")
A11: basic | B11: =COUNTIF('케이스 결과'!A2:A148,A11) | C11: =COUNTIFS('케이스 결과'!A2:A148,A11,'케이스 결과'!I2:I148,"실패")
A12: complain | B12: =COUNTIF('케이스 결과'!A2:A148,A12) | C12: =COUNTIFS('케이스 결과'!A2:A148,A12,'케이스 결과'!I2:I148,"실패")
A13: contradict | B13: =COUNTIF('케이스 결과'!A2:A148,A13) | C13: =COUNTIFS('케이스 결과'!A2:A148,A13,'케이스 결과'!I2:I148,"실패")
A14: dest | B14: =COUNTIF('케이스 결과'!A2:A148,A14) | C14: =COUNTIFS('케이스 결과'!A2:A148,A14,'케이스 결과'!I2:I148,"실패")
A15: dup | B15: =COUNTIF('케이스 결과'!A2:A148,A15) | C15: =COUNTIFS('케이스 결과'!A2:A148,A15,'케이스 결과'!I2:I148,"실패")
A16: edit | B16: =COUNTIF('케이스 결과'!A2:A148,A16) | C16: =COUNTIFS('케이스 결과'!A2:A148,A16,'케이스 결과'!I2:I148,"실패")
A17: english | B17: =COUNTIF('케이스 결과'!A2:A148,A17) | C17: =COUNTIFS('케이스 결과'!A2:A148,A17,'케이스 결과'!I2:I148,"실패")
A18: garbage | B18: =COUNTIF('케이스 결과'!A2:A148,A18) | C18: =COUNTIFS('케이스 결과'!A2:A148,A18,'케이스 결과'!I2:I148,"실패")
A19: inject | B19: =COUNTIF('케이스 결과'!A2:A148,A19) | C19: =COUNTIFS('케이스 결과'!A2:A148,A19,'케이스 결과'!I2:I148,"실패")
A20: longmsg | B20: =COUNTIF('케이스 결과'!A2:A148,A20) | C20: =COUNTIFS('케이스 결과'!A2:A148,A20,'케이스 결과'!I2:I148,"실패")
A21: maxuse | B21: =COUNTIF('케이스 결과'!A2:A148,A21) | C21: =COUNTIFS('케이스 결과'!A2:A148,A21,'케이스 결과'!I2:I148,"실패")
A22: mixed | B22: =COUNTIF('케이스 결과'!A2:A148,A22) | C22: =COUNTIFS('케이스 결과'!A2:A148,A22,'케이스 결과'!I2:I148,"실패")
A23: multilang | B23: =COUNTIF('케이스 결과'!A2:A148,A23) | C23: =COUNTIFS('케이스 결과'!A2:A148,A23,'케이스 결과'!I2:I148,"실패")
A24: negation | B24: =COUNTIF('케이스 결과'!A2:A148,A24) | C24: =COUNTIFS('케이스 결과'!A2:A148,A24,'케이스 결과'!I2:I148,"실패")
A25: nonplace | B25: =COUNTIF('케이스 결과'!A2:A148,A25) | C25: =COUNTIFS('케이스 결과'!A2:A148,A25,'케이스 결과'!I2:I148,"실패")
A26: numtrap | B26: =COUNTIF('케이스 결과'!A2:A148,A26) | C26: =COUNTIFS('케이스 결과'!A2:A148,A26,'케이스 결과'!I2:I148,"실패")
A27: offtopic | B27: =COUNTIF('케이스 결과'!A2:A148,A27) | C27: =COUNTIFS('케이스 결과'!A2:A148,A27,'케이스 결과'!I2:I148,"실패")
A28: people | B28: =COUNTIF('케이스 결과'!A2:A148,A28) | C28: =COUNTIFS('케이스 결과'!A2:A148,A28,'케이스 결과'!I2:I148,"실패")
A29: privacy | B29: =COUNTIF('케이스 결과'!A2:A148,A29) | C29: =COUNTIFS('케이스 결과'!A2:A148,A29,'케이스 결과'!I2:I148,"실패")
A30: question | B30: =COUNTIF('케이스 결과'!A2:A148,A30) | C30: =COUNTIFS('케이스 결과'!A2:A148,A30,'케이스 결과'!I2:I148,"실패")
A31: social | B31: =COUNTIF('케이스 결과'!A2:A148,A31) | C31: =COUNTIFS('케이스 결과'!A2:A148,A31,'케이스 결과'!I2:I148,"실패")
A32: spacing | B32: =COUNTIF('케이스 결과'!A2:A148,A32) | C32: =COUNTIFS('케이스 결과'!A2:A148,A32,'케이스 결과'!I2:I148,"실패")
A33: timetrap | B33: =COUNTIF('케이스 결과'!A2:A148,A33) | C33: =COUNTIFS('케이스 결과'!A2:A148,A33,'케이스 결과'!I2:I148,"실패")
A34: typo | B34: =COUNTIF('케이스 결과'!A2:A148,A34) | C34: =COUNTIFS('케이스 결과'!A2:A148,A34,'케이스 결과'!I2:I148,"실패")
A35: voice | B35: =COUNTIF('케이스 결과'!A2:A148,A35) | C35: =COUNTIFS('케이스 결과'!A2:A148,A35,'케이스 결과'!I2:I148,"실패")
A37: LLM(gpt-5.6-sol) 실측
A38: LLM 통과 | B38: 133
A39: LLM 실패 | B39: 12
A40: LLM 무응답 | B40: 0

Sheet LLM 결과
A1: 범주 | B1: 물음(입력) | C1: 뽑은 경유지 | D1: 도착 마감 | E1: 이동수단 | F1: 순서 | G1: 거절 | H1: 되묻기 | I1: 판정 | J1: 실패 사유 | K1: 메모
A2: basic | B2: 출근길에 올리브영 들르고 빵도 사가고 싶어 | C2: 올리브영, 빵집, 베이커리 | F2: auto | I2: 통과
A3: basic | B3: 9시까지 회사 가야 하는데 커피 사고 은행도 들러야 해 | C3: 카페, 커피숍, 은행 | D3: 09:00 | F3: auto | I3: 통과
A4: basic | B4: 택배 부치고 약국 갔다가 회사 | C4: 우체국, 편의점, 약국 | F4: locked | I4: 통과
A5: basic | B5: 강남역 스타벅스 들렀다 가자 | C5: 강남역 스타벅스 | F5: auto | I5: 통과
A6: basic | B6: 지하철로 갈래 | E6: transit | F6: auto | I6: 통과
A7: basic | B7: 문 연 약국만 | C7: 약국 | F7: auto | I7: 통과
A8: basic | B8: 은행 먼저 갔다가 우체국 | C8: 은행, 우체국 | F8: locked | I8: 통과
A9: basic | B9: 올리브영 3개 들러서 비교해볼래 | C9: 올리브영 | F9: auto | I9: 통과
A10: typo | B10: 올리브용 들르고 싶어 | C10: 올리브영 | F10: auto | I10: 통과 | K10: 오타 교정 — Codex 통과, 목 실패
A11: typo | B11: 스타벅쓰 들렀다 가자 | C11: 스타벅스 | F11: auto | I11: 통과 | K11: 오타 교정
A12: typo | B12: 파리바게트 들러줘 | C12: 파리바게뜨 | F12: auto | I12: 통과 | K12: 표기 오류 교정
A13: typo | B13: 편의젬 들러야해 | C13: 편의점 | F13: auto | I13: 통과 | K13: 오타 교정
A14: typo | B14: 9시 까 지 도착 | D14: 09:00 | F14: auto | I14: 통과 | K14: 띄어쓰기 파괴
A15: abbrev | B15: 올영 들러야 해 | C15: 올리브영 | F15: auto | I15: 통과 | K15: 줄임말
A16: abbrev | B16: 스벅에서 커피 | C16: 스타벅스 | F16: auto | I16: 통과 | K16: 스벅은 못 잡아도 커피로 잡힘
A17: abbrev | B17: 파바 들르자 | C17: 파리바게뜨 | F17: auto | I17: 통과 | K17: 줄임말
A18: abbrev | B18: 다이소 들를래 | C18: 다이소 | F18: auto | I18: 실패 | J18: 되묻지 않음 | K18: 사전 밖 브랜드 — 되묻는다
A19: abbrev | B19: 메가커피 갈래 | C19: 메가MGC커피, 메가커피 | F19: auto | I19: 실패 | J19: qhas 스타벅스,카페 | K19: 커피로 잡힘
A20: spacing | B20: 올리브영들르고빵도사고싶어 | C20: 올리브영, 빵집, 베이커리 | F20: auto | I20: 통과 | K20: 띄어쓰기 없음
A21: spacing | B21: 9시까지회사 | D21: 09:00 | F21: auto | I21: 통과
A22: spacing | B22: 약국이랑은행 | C22: 약국, 은행 | F22: auto | I22: 통과
A23: spacing | B23: 커피사고은행들러야해 | C23: 카페, 커피숍, 은행 | F23: locked | I23: 통과
A24: english | B24: olive young 들러줘 | C24: 올리브영 | F24: auto | I24: 통과 | K24: 영문 브랜드
A25: english | B25: starbucks 들렀다 가자 | C25: 스타벅스 | F25: auto | I25: 통과 | K25: 영문 브랜드
A26: english | B26: CU 들러서 담배 | C26: CU | F26: auto | I26: 통과 | K26: 영문이 정식 표기
A27: english | B27: GS25 잠깐 | C27: GS25 | F27: auto | I27: 통과
A28: english | B28: pharmacy 들러야 해 | C28: 약국, pharmacy | F28: auto | I28: 통과 | K28: 영어 카테고리
A29: numtrap | B29: 2호선 타고 갈래 | E29: transit | F29: auto | I29: 통과 | K29: 2를 개수로 읽으면 안 된다
A30: numtrap | B30: 3번 출구에서 만나기로 했어 | F30: auto | H30: 어느 역의 3번 출구인가요? | I30: 통과 | K30: 3은 출구 번호
A31: numtrap | B31: 올리브영 1층에 있어 | F31: auto | I31: 통과 | K31: 1은 층수
A32: numtrap | B32: 24시간 편의점 들러줘 | C32: 24시간 편의점, 편의점 | F32: auto | I32: 통과 | K32: 24는 개수가 아니다
A33: numtrap | B33: CU 여의도2호점 | C33: CU 여의도2호점 | F33: auto | I33: 통과 | K33: 2호점은 개수가 아니다
A34: numtrap | B34: 샌드위치 2개 사기 | C34: 샌드위치 가게, 편의점, 카페 | F34: auto | I34: 통과 | K34: 물건 개수
A35: numtrap | B35: 아메리카노 두 잔 사고 | C35: 카페, 커피숍 | F35: auto | I35: 통과 | K35: 잔은 장소 단위가 아니다
A36: numtrap | B36: 5천원짜리 빵 | C36: 빵집, 베이커리 | F36: auto | I36: 통과 | K36: 금액
A37: timetrap | B37: 3시간 걸려도 괜찮아 | F37: auto | I37: 통과 | K37: 길찾기 맥락 — 거절하면 안 된다
A38: timetrap | B38: 5분 거리에 있는 편의점 | C38: 편의점 | F38: auto | I38: 통과
A39: timetrap | B39: 1시간 뒤에 출발할 거야 | F39: auto | I39: 통과 | K39: 길찾기 맥락 — 거절하면 안 된다
A40: timetrap | B40: 10분만 들렀다 갈게 | F40: auto | I40: 통과 | K40: 체류시간
...

Sheet 개선 이력
A1: 날짜 | B1: 스키마 | C1: 무엇이 문제였나 | D1: 왜 문제였나 | E1: 어떻게 고쳤나 | F1: 효과
A2: 2026-09-10 | B2: v1→v2 | C2: 같은 브랜드를 여러 곳 요청해도 1곳으로 처리 | D2: 스키마에 count가 없었다 | E2: IntentStop.count 추가 | F2: "올리브영 3개" 통과
A3: 2026-09-10 | B3: v1→v2 | C3: "빵집 빼줘"를 해석 못 함 | D3: 프롬프트가 무상태였다. 채팅은 한 번에 끝나지 않는다 | E3: 입력에 currentStops 추가 | F3: 대화형 수정 가능
A4: 2026-09-10 | B4: v1→v2 | C4: "택배"를 우체국으로 단정 | D4: 카테고리를 하나로 좁혀 넘겨짚었다 | E4: queries를 배열로 — 후보를 여럿 낸다 | F4: 편의점도 후보에 남음
A5: 2026-09-10 | B5: v2→v3 | C5: "회사 말고 집으로" 표현 불가 | D5: 목적지 변경을 담을 자리가 스키마에 없었다 | E5: endpoints 추가. 좌표 아는 곳만 적용, 아니면 되묻기 | F5: 목적지/출발지 변경 통과
A6: 2026-09-10 | B6: v2→v3 | C6: "올리브영 대신 이마트" 표현 불가 | D6: op이 문장당 하나여서 제거+추가를 못 담았다 | E6: op을 경유지마다 붙임 | F6: 교체 통과
A7: 2026-09-10 | B7: v2→v3 | C7: "순서 바꿔줘" 표현 불가 | D7: orderLocked가 boolean이라 3번째 상태가 없었다 | E7: order: auto|locked|reshuffle | F7: 순서 변경 통과
A8: 2026-09-10 | B8: v3 | C8: 못 알아들은 요청과 인사가 똑같이 침묵 | D8: 빈 결과에 되묻기가 없어 사용자는 앱이 죽은 줄 안다 | E8: 요청처럼 보이는데 아무것도 못 뽑으면 ambiguous | F8: 오타·줄임말·영문·다국어 12건이 되묻기로
A9: 2026-09-10 | B9: v3 | C9: "올리브영은 안 들러도 돼"가 올리브영을 경유지로 만듦 | D9: 부정문을 보지 않아 정반대로 동작 | E9: 부정어 뒤만 추출 범위로 자름 | F9: "커피는 됐고 은행만"의 은행도 살아남음
A10: 2026-09-10 | B10: v3 | C10: "지하철로 걸어서 차로" 중 하나를 임의 선택 | D10: 충돌인데 고르면 절반은 틀린다 | E10: 충돌 감지 → 되묻기 | F10: 오답 대신 질문
A11: 2026-09-10 | B11: v3 | C11: 마감이 여럿일 때 마지막 것 사용 | D11: 늦은 마감을 고르면 지각한다 | E11: 가장 이른 것 채택 | F11: 마감은 빡빡한 쪽으로
A12: 2026-09-10 | B12: v3 | C12: 프롬프트 인젝션에 무방비 | D12: "이전 지시 무시" 같은 말을 거르지 않음 | E12: 1차선: reject / 실제 방어선: 서버 schema.ts 검증 | F12: LLM이 뭘 뱉든 스키마 통과 필수
... A30: 2026-09-15 | B30: 리스크 | C30: 같은 문장이 codex 는 통과, API 는 실패 | D30: 같은 규칙·같은 모델인데 결과가 갈린다 | E30: 기록만 한다. 1건을 위해 라운드를 더 돌지 않는다 | F30: 비결정성은 칩 UI 로 흡수한다 — 사용자가 보고 고친다

Sheet 쓰는 법
A1: 이 파일은 손으로 채우지 않는다
A3: 1. 케이스를 추가한다 | B3: server/prompts/cases.jsonl 에 한 줄 추가
A4: 2. 돌린다 | B4: node server/run-cases.mjs
A5: 3. 엑셀을 다시 만든다 | B5: node server/run-cases.mjs --json > server/results.json 후 스크립트 실행
A7: 판정의 뜻
A8: 통과 | B8: 기대값을 만족했다
A9: 실패 | B9: 기대값과 어긋났다 — 실패 사유 열을 본다
A10: 미검증 | B10: note만 있고 기대값이 없다. 통과가 아니다 — 기대값을 정해야 한다
A12: 지금 재는 대상 | B12: 로컬 목(src/lib/intent.ts)이지 LLM이 아니다.
B13: OpenAI를 붙인 뒤 같은 147개를 서버로 돌려 이 기준선과 비교한다.
B14: 목이 통과한 것을 LLM이 실패할 수도, 그 반대일 수도 있다.
A16: 개선 이력을 쌓는 이유 | B16: 같은 실수를 두 번 하지 않기 위해서다.
B17: 실패를 고칠 때마다 무엇이/왜/어떻게를 한 줄 남긴다.
